// Try...catch works synchronously

// try catch dont work in below code
// try {
//     setTimeout(() => {
//         username;
//     }, 1000)
// } 
// catch(err) {
//     console.log('You have an error!')
// }

// try..catch works in below code compared to above code
// setTimeout(()=>{
//     try{
//         username;
//     }
//     catch(err){
//         console.log('You have an error!')
//     }
// }, 1000)
